Workbook

Sheet Assumptions
B1: ShopSmart Retail Analytics & AI Implementation Project
B2: AnalystLab Africa PM Internship, Week 2: Assumptions and legend
B4: Project start date | C4: 46328
B5: Working week | C5: Monday to Friday
B6: Currency | C6: Nigerian Naira (indicative estimates)
B8: Non working days (Nigerian public holidays)
B9: Christmas Day | C9: 46381
B10: Boxing Day (observed) | C10: 46384
B11: New Year's Day | C11: 46388
B12: Good Friday | C12: 46472
B13: Easter Monday | C13: 46475
B14: Workers' Day (observed) | C14: 46510
B16: Legend
B17: Blue text | C17: Input (change to re-plan: start date, holidays, durations, quantities, rates)
B18: Black text | C18: Formula (do not overwrite)
B19: Yellow cell | C19: Key assumption: project start date
B21: Key planning assumptions
B22: 1. All dependencies are Finish to Start with no lag.
B23: 2. Durations are in working days. Dates calculate from the start date, skipping weekends and listed holidays.
B24: 3. Moveable religious holidays (for example Eid) are not pre loaded. Add them to the holiday list if declared.
B25: 4. Critical path uses the Critical Path Method (forward and backward pass). Float = Late Start minus Early Start.
B26: 5. Costs are indicative Naira estimates built from role day rates, licence prices and cloud run rates.
B27: 6. Contingency reserve is 12% of the base budget because data quality, API limits and price changes add uncertainty.
B28: 7. The Week 1 baseline (Charter, Scope Statement, WBS, Risk Register, Communication Plan) is approved. Out of scope: ERP, mobile apps, live production deployment, payment gateway, loyalty system.

Sheet Schedule
B4: Activity ID | C4: Activity Name | D4: Phase | E4: Duration (days) | F4: Start Date | G4: Finish Date | H4: Dependencies (Predecessors) | I4: Assigned Resource | J4: Early Start (day) | K4: Early Finish (day) | L4: Late Start (day) | M4: Late Finish (day) | N4: Total Float (days) | O4: Critical?
B5: A01 | C5: Project kick-off and sign-off of execution plan | D5: 1. Initiation & Mobilisation | E5: 2 | F5: =WORKDAY(Assumptions!$C$4-1,J5+1,Assumptions!$C$9:$C$14) -> 46328 | G5: =WORKDAY(Assumptions!$C$4-1,K5,Assumptions!$C$9:$C$14) -> 46329 | H5: None | I5: Project Manager | J5: 0 | K5: =J5+E5 -> 2 | L5: =M5-E5 -> 0 | M5: =MIN(L6,L7) -> 2 | N5: =L5-J5 -> 0 | O5: =IF(N5=0,"Yes","No") -> Yes
B6: A02 | C6: Tools, access and environment setup (Power BI, Python, GitHub, API keys) | D6: 1. Initiation & Mobilisation | E6: 3 | F6: =WORKDAY(Assumptions!$C$4-1,J6+1,Assumptions!$C$9:$C$14) -> 46330 | G6: =WORKDAY(Assumptions!$C$4-1,K6,Assumptions!$C$9:$C$14) -> 46332 | H6: A01 | I6: Project Manager, Data Analyst | J6: =MAX(K5) -> 2 | K6: =J6+E6 -> 5 | L6: =M6-E6 -> 3 | M6: =MIN(L9) -> 6 | N6: =L6-J6 -> 1 | O6: =IF(N6=0,"Yes","No") -> No
B7: A03 | C7: Dataset handover and file validation (9 CSV files and data dictionary) | D7: 1. Initiation & Mobilisation | E7: 4 | F7: =WORKDAY(Assumptions!$C$4-1,J7+1,Assumptions!$C$9:$C$14) -> 46330 | G7: =WORKDAY(Assumptions!$C$4-1,K7,Assumptions!$C$9:$C$14) -> 46335 | H7: A01 | I7: Business Analyst, Data Analyst | J7: =MAX(K5) -> 2 | K7: =J7+E7 -> 6 | L7: =M7-E7 -> 2 | M7: =MIN(L9) -> 6 | N7: =L7-J7 -> 0 | O7: =IF(N7=0,"Yes","No") -> Yes
B9: M1 | C9: Milestone: Project Mobilised | D9: 1. Initiation & Mobilisation | E9: 0 | F9: =G9 -> 46335 | G9: =WORKDAY(Assumptions!$C$4-1,K9,Assumptions!$C$9:$C$14) -> 46335 | H9: A02, A03 | I9: Project Manager | J9: =MAX(K6,K7) -> 6 | K9: =J9+E9 -> 6 | L9: =M9-E9 -> 6 | M9: =MIN(L10,L13) -> 6 | N9: =L9-J9 -> 0 | O9: =IF(N9=0,"Yes","No") -> Yes
B10: A04 | C10: Data profiling and quality assessment | D10: 2. Data Preparation & Requirements | E10: 5 | F10: =WORKDAY(Assumptions!$C$4-1,J10+1,Assumptions!$C$9:$C$14) -> 46336 | G10: =WORKDAY(Assumptions!$C$4-1,K10,Assumptions!$C$9:$C$14) -> 46342 | H10: M1 | I10: Data Scientist, Data Analyst | J10: =MAX(K9) -> 6 | K10: =J10+E10 -> 11 | L10: =M10-E10 -> 6 | M10: =MIN(L11) -> 11 | N10: =L10-J10 -> 0 | O10: =IF(N10=0,"Yes","No") -> Yes
B11: A05 | C11: Data cleaning and standardisation | D11: 2. Data Preparation & Requirements | E11: 8 | F11: =WORKDAY(Assumptions!$C$4-1,J11+1,Assumptions!$C$9:$C$14) -> 46343 | G11: =WORKDAY(Assumptions!$C$4-1,K11,Assumptions!$C$9:$C$14) -> 46352 | H11: A04 | I11: Data Scientist, Data Analyst | J11: =MAX(K10) -> 11 | K11: =J11+E11 -> 19 | L11: =M11-E11 -> 11 | M11: =MIN(L12) -> 19 | N11: =L11-J11 -> 0 | O11: =IF(N11=0,"Yes","No") -> Yes
B12: A06 | C12: Data validation and reconciliation checks | D12: 2. Data Preparation & Requirements | E12: 4 | F12: =WORKDAY(Assumptions!$C$4-1,J12+1,Assumptions!$C$9:$C$14) -> 46353 | G12: =WORKDAY(Assumptions!$C$4-1,K12,Assumptions!$C$9:$C$14) -> 46358 | H12: A05 | I12: Data Scientist, QA Tester | J12: =MAX(K11) -> 19 | K12: =J12+E12 -> 23 | L12: =M12-E12 -> 19 | M12: =MIN(L15) -> 23 | N12: =L12-J12 -> 0 | O12: =IF(N12=0,"Yes","No") -> Yes
B13: A07 | C13: Requirements workshops with ShopSmart managers | D13: 2. Data Preparation & Requirements | E13: 6 | F13: =WORKDAY(Assumptions!$C$4-1,J13+1,Assumptions!$C$9:$C$14) -> 46336 | G13: =WORKDAY(Assumptions!$C$4-1,K13,Assumptions!$C$9:$C$14) -> 46343 | H13: M1 | I13: Business Analyst, Project Manager | J13: =MAX(K9) -> 6 | K13: =J13+E13 -> 12 | L13: =M13-E13 -> 17 | M13: =MIN(L15) -> 23 | N13: =L13-J13 -> 11 | O13: =IF(N13=0,"Yes","No") -> No
B15: M2 | C15: Milestone: Clean Dataset and Requirements Baselined | D15: 2. Data Preparation & Requirements | E15: 0 | F15: =G15 -> 46358 | G15: =WORKDAY(Assumptions!$C$4-1,K15,Assumptions!$C$9:$C$14) -> 46358 | H15: A06, A07 | I15: Project Manager | J15: =MAX(K12,K13) -> 23 | K15: =J15+E15 -> 23 | L15: =M15-E15 -> 23 | M15: =MIN(L16,L17,L18,L29) -> 23 | N15: =L15-J15 -> 0 | O15: =IF(N15=0,"Yes","No") -> Yes
B16: A08 | C16: Exploratory data analysis and statistical insights | D16: 3. Data Analytics & Data Science | E16: 7 | F16: =WORKDAY(Assumptions!$C$4-1,J16+1,Assumptions!$C$9:$C$14) -> 46359 | G16: =WORKDAY(Assumptions!$C$4-1,K16,Assumptions!$C$9:$C$14) -> 46367 | H16: M2 | I16: Data Scientist | J16: =MAX(K15) -> 23 | K16: =J16+E16 -> 30 | L16: =M16-E16 -> 23 | M16: =MIN(L22) -> 30 | N16: =L16-J16 -> 0 | O16: =IF(N16=0,"Yes","No") -> Yes
B17: A09 | C17: Sales dashboard development | D17: 3. Data Analytics & Data Science | E17: 8 | F17: =WORKDAY(Assumptions!$C$4-1,J17+1,Assumptions!$C$9:$C$14) -> 46359 | G17: =WORKDAY(Assumptions!$C$4-1,K17,Assumptions!$C$9:$C$14) -> 46370 | H17: M2 | I17: Data Analyst | J17: =MAX(K15) -> 23 | K17: =J17+E17 -> 31 | L17: =M17-E17 -> 41 | M17: =MIN(L19) -> 49 | N17: =L17-J17 -> 18 | O17: =IF(N17=0,"Yes","No") -> No
B18: A10 | C18: Customer dashboard development | D18: 3. Data Analytics & Data Science | E18: 7 | F18: =WORKDAY(Assumptions!$C$4-1,J18+1,Assumptions!$C$9:$C$14) -> 46359 | G18: =WORKDAY(Assumptions!$C$4-1,K18,Assumptions!$C$9:$C$14) -> 46367 | H18: M2 | I18: Data Analyst | J18: =MAX(K15) -> 23 | K18: =J18+E18 -> 30 | L18: =M18-E18 -> 42 | M18: =MIN(L20) -> 49 | N18: =L18-J18 -> 19 | O18: =IF(N18=0,"Yes","No") -> No
B19: A11 | C19: Store performance dashboard development | D19: 3. Data Analytics & Data Science | E19: 6 | F19: =WORKDAY(Assumptions!$C$4-1,J19+1,Assumptions!$C$9:$C$14) -> 46371 | G19: =WORKDAY(Assumptions!$C$4-1,K19,Assumptions!$C$9:$C$14) -> 46378 | H19: A09 | I19: Data Analyst | J19: =MAX(K17) -> 31 | K19: =J19+E19 -> 37 | L19: =M19-E19 -> 49 | M19: =MIN(L21) -> 55 | N19: =L19-J19 -> 18 | O19: =IF(N19=0,"Yes","No") -> No
B20: A12 | C20: Inventory dashboard development | D20: 3. Data Analytics & Data Science | E20: 6 | F20: =WORKDAY(Assumptions!$C$4-1,J20+1,Assumptions!$C$9:$C$14) -> 46370 | G20: =WORKDAY(Assumptions!$C$4-1,K20,Assumptions!$C$9:$C$14) -> 46377 | H20: A10 | I20: Data Analyst | J20: =MAX(K18) -> 30 | K20: =J20+E20 -> 36 | L20: =M20-E20 -> 49 | M20: =MIN(L21) -> 55 | N20: =L20-J20 -> 19 | O20: =IF(N20=0,"Yes","No") -> No
B21: A13 | C21: Executive analytics report | D21: 3. Data Analytics & Data Science | E21: 4 | F21: =WORKDAY(Assumptions!$C$4-1,J21+1,Assumptions!$C$9:$C$14) -> 46379 | G21: =WORKDAY(Assumptions!$C$4-1,K21,Assumptions!$C$9:$C$14) -> 46386 | H21: A11, A12 | I21: Business Analyst, Data Analyst | J21: =MAX(K19,K20) -> 37 | K21: =J21+E21 -> 41 | L21: =M21-E21 -> 55 | M21: =MIN(L24) -> 59 | N21: =L21-J21 -> 18 | O21: =IF(N21=0,"Yes","No") -> No
B22: A14 | C22: Feature engineering pipeline | D22: 3. Data Analytics & Data Science | E22: 8 | F22: =WORKDAY(Assumptions!$C$4-1,J22+1,Assumptions!$C$9:$C$14) -> 46370 | G22: =WORKDAY(Assumptions!$C$4-1,K22,Assumptions!$C$9:$C$14) -> 46379 | H22: A08 | I22: Data Scientist | J22: =MAX(K16) -> 30 | K22: =J22+E22 -> 38 | L22: =M22-E22 -> 30 | M22: =MIN(L24,L25,L26) -> 38 | N22: =L22-J22 -> 0 | O22: =IF(N22=0,"Yes","No") -> Yes
B24: M3 | C24: Milestone: Analytics and Feature Pipeline Complete | D24: 3. Data Analytics & Data Science | E24: 0 | F24: =G24 -> 46386 | G24: =WORKDAY(Assumptions!$C$4-1,K24,Assumptions!$C$9:$C$14) -> 46386 | H24: A13, A14 | I24: Project Manager | J24: =MAX(K21,K22) -> 41 | K24: =J24+E24 -> 41 | L24: =M24-E24 -> 59 | M24: =MIN(L34) -> 59 | N24: =L24-J24 -> 18 | O24: =IF(N24=0,"Yes","No") -> No
B25: A15 | C25: Sales forecasting model development | D25: 4. Machine Learning | E25: 12 | F25: =WORKDAY(Assumptions!$C$4-1,J25+1,Assumptions!$C$9:$C$14) -> 46380 | G25: =WORKDAY(Assumptions!$C$4-1,K25,Assumptions!$C$9:$C$14) -> 46400 | H25: A14 | I25: Machine Learning Engineer | J25: =MAX(K22) -> 38 | K25: =J25+E25 -> 50 | L25: =M25-E25 -> 42 | M25: =MIN(L28,L32) -> 54 | N25: =L25-J25 -> 4 | O25: =IF(N25=0,"Yes","No") -> No
B26: A16 | C26: Customer segmentation model | D26: 4. Machine Learning | E26: 8 | F26: =WORKDAY(Assumptions!$C$4-1,J26+1,Assumptions!$C$9:$C$14) -> 46380 | G26: =WORKDAY(Assumptions!$C$4-1,K26,Assumptions!$C$9:$C$14) -> 46394 | H26: A14 | I26: Data Scientist | J26: =MAX(K22) -> 38 | K26: =J26+E26 -> 46 | L26: =M26-E26 -> 38 | M26: =MIN(L27) -> 46 | N26: =L26-J26 -> 0 | O26: =IF(N26=0,"Yes","No") -> Yes
B27: A17 | C27: Product recommendation prototype | D27: 4. Machine Learning | E27: 8 | F27: =WORKDAY(Assumptions!$C$4-1,J27+1,Assumptions!$C$9:$C$14) -> 46395 | G27: =WORKDAY(Assumptions!$C$4-1,K27,Assumptions!$C$9:$C$14) -> 46406 | H27: A16 | I27: Data Scientist, Machine Learning Engineer | J27: =MAX(K26) -> 46 | K27: =J27+E27 -> 54 | L27: =M27-E27 -> 46 | M27: =MIN(L28) -> 54 | N27: =L27-J27 -> 0 | O27: =IF(N27=0,"Yes","No") -> Yes
B28: A18 | C28: Model evaluation and evaluation report | D28: 4. Machine Learning | E28: 5 | F28: =WORKDAY(Assumptions!$C$4-1,J28+1,Assumptions!$C$9:$C$14) -> 46407 | G28: =WORKDAY(Assumptions!$C$4-1,K28,Assumptions!$C$9:$C$14) -> 46413 | H28: A15, A17 | I28: Machine Learning Engineer, QA Tester | J28: =MAX(K25,K27) -> 54 | K28: =J28+E28 -> 59 | L28: =M28-E28 -> 54 | M28: =MIN(L34) -> 59 | N28: =L28-J28 -> 0 | O28: =IF(N28=0,"Yes","No") -> Yes
B29: A19 | C29: Prompt library design and testing | D29: 5. Generative AI | E29: 8 | F29: =WORKDAY(Assumptions!$C$4-1,J29+1,Assumptions!$C$9:$C$14) -> 46359 | G29: =WORKDAY(Assumptions!$C$4-1,K29,Assumptions!$C$9:$C$14) -> 46370 | H29: M2 | I29: Generative AI Engineer | J29: =MAX(K15) -> 23 | K29: =J29+E29 -> 31 | L29: =M29-E29 -> 27 | M29: =MIN(L30) -> 35 | N29: =L29-J29 -> 4 | O29: =IF(N29=0,"Yes","No") -> No
B30: A20 | C30: Retail report generator | D30: 5. Generative AI | E30: 7 | F30: =WORKDAY(Assumptions!$C$4-1,J30+1,Assumptions!$C$9:$C$14) -> 46371 | G30: =WORKDAY(Assumptions!$C$4-1,K30,Assumptions!$C$9:$C$14) -> 46379 | H30: A19 | I30: Generative AI Engineer | J30: =MAX(K29) -> 31 | K30: =J30+E30 -> 38 | L30: =M30-E30 -> 35 | M30: =MIN(L31) -> 42 | N30: =L30-J30 -> 4 | O30: =IF(N30=0,"Yes","No") -> No
B31: A21 | C31: AI Retail Copilot development (Streamlit) | D31: 5. Generative AI | E31: 12 | F31: =WORKDAY(Assumptions!$C$4-1,J31+1,Assumptions!$C$9:$C$14) -> 46380 | G31: =WORKDAY(Assumptions!$C$4-1,K31,Assumptions!$C$9:$C$14) -> 46400 | H31: A20 | I31: Generative AI Engineer | J31: =MAX(K30) -> 38 | K31: =J31+E31 -> 50 | L31: =M31-E31 -> 42 | M31: =MIN(L32) -> 54 | N31: =L31-J31 -> 4 | O31: =IF(N31=0,"Yes","No") -> No
B32: A22 | C32: Copilot integration with data and forecasting model | D32: 5. Generative AI | E32: 5 | F32: =WORKDAY(Assumptions!$C$4-1,J32+1,Assumptions!$C$9:$C$14) -> 46401 | G32: =WORKDAY(Assumptions!$C$4-1,K32,Assumptions!$C$9:$C$14) -> 46407 | H32: A21, A15 | I32: Generative AI Engineer, Machine Learning Engineer | J32: =MAX(K31,K25) -> 50 | K32: =J32+E32 -> 55 | L32: =M32-E32 -> 54 | M32: =MIN(L34) -> 59 | N32: =L32-J32 -> 4 | O32: =IF(N32=0,"Yes","No") -> No
B34: M4 | C34: Milestone: All Workstream Deliverables Built | D34: 6. Testing & Quality Assurance | E34: 0 | F34: =G34 -> 46413 | G34: =WORKDAY(Assumptions!$C$4-1,K34,Assumptions!$C$9:$C$14) -> 46413 | H34: A18, A22, M3 | I34: Project Manager | J34: =MAX(K28,K32,K24) -> 59 | K34: =J34+E34 -> 59 | L34: =M34-E34 -> 59 | M34: =MIN(L35,L36,L37,L42) -> 59 | N34: =L34-J34 -> 0 | O34: =IF(N34=0,"Yes","No") -> Yes
B35: A23 | C35: Dashboard quality review and data accuracy testing | D35: 6. Testing & Quality Assurance | E35: 4 | F35: =WORKDAY(Assumptions!$C$4-1,J35+1,Assumptions!$C$9:$C$14) -> 46414 | G35: =WORKDAY(Assumptions!$C$4-1,K35,Assumptions!$C$9:$C$14) -> 46419 | H35: M4 | I35: QA Tester, Data Analyst | J35: =MAX(K34) -> 59 | K35: =J35+E35 -> 63 | L35: =M35-E35 -> 61 | M35: =MIN(L38) -> 65 | N35: =L35-J35 -> 2 | O35: =IF(N35=0,"Yes","No") -> No
B36: A24 | C36: Code review and model testing | D36: 6. Testing & Quality Assurance | E36: 5 | F36: =WORKDAY(Assumptions!$C$4-1,J36+1,Assumptions!$C$9:$C$14) -> 46414 | G36: =WORKDAY(Assumptions!$C$4-1,K36,Assumptions!$C$9:$C$14) -> 46420 | H36: M4 | I36: QA Tester, Machine Learning Engineer | J36: =MAX(K34) -> 59 | K36: =J36+E36 -> 64 | L36: =M36-E36 -> 60 | M36: =MIN(L38) -> 65 | N36: =L36-J36 -> 1 | O36: =IF(N36=0,"Yes","No") -> No
B37: A25 | C37: Copilot testing and prompt evaluation | D37: 6. Testing & Quality Assurance | E37: 6 | F37: =WORKDAY(Assumptions!$C$4-1,J37+1,Assumptions!$C$9:$C$14) -> 46414 | G37: =WORKDAY(Assumptions!$C$4-1,K37,Assumptions!$C$9:$C$14) -> 46421 | H37: M4 | I37: QA Tester, Generative AI Engineer | J37: =MAX(K34) -> 59 | K37: =J37+E37 -> 65 | L37: =M37-E37 -> 59 | M37: =MIN(L38) -> 65 | N37: =L37-J37 -> 0 | O37: =IF(N37=0,"Yes","No") -> Yes
B38: A26 | C38: User acceptance testing with ShopSmart managers | D38: 6. Testing & Quality Assurance | E38: 5 | F38: =WORKDAY(Assumptions!$C$4-1,J38+1,Assumptions!$C$9:$C$14) -> 46422 | G38: =WORKDAY(Assumptions!$C$4-1,K38,Assumptions!$C$9:$C$14) -> 46428 | H38: A23, A24, A25 | I38: Business Analyst, QA Tester | J38: =MAX(K35,K36,K37) -> 65 | K38: =J38+E38 -> 70 | L38: =M38-E38 -> 65 | M38: =MIN(L39) -> 70 | N38: =L38-J38 -> 0 | O38: =IF(N38=0,"Yes","No") -> Yes
B39: A27 | C39: Defect fixing and retesting | D39: 6. Testing & Quality Assurance | E39: 5 | F39: =WORKDAY(Assumptions!$C$4-1,J39+1,Assumptions!$C$9:$C$14) -> 46429 | G39: =WORKDAY(Assumptions!$C$4-1,K39,Assumptions!$C$9:$C$14) -> 46435 | H39: A26 | I39: Data Analyst, Machine Learning Engineer, Generative AI Engineer | J39: =MAX(K38) -> 70 | K39: =J39+E39 -> 75 | L39: =M39-E39 -> 70 | M39: =MIN(L41) -> 75 | N39: =L39-J39 -> 0 | O39: =IF(N39=0,"Yes","No") -> Yes
B41: M5 | C41: Milestone: Deliverables Accepted | D41: 6. Testing & Quality Assurance | E41: 0 | F41: =G41 -> 46435 | G41: =WORKDAY(Assumptions!$C$4-1,K41,Assumptions!$C$9:$C$14) -> 46435 | H41: A27 | I41: Project Manager | J41: =MAX(K39) -> 75 | K41: =J41+E41 -> 75 | L41: =M41-E41 -> 75 | M41: =MIN(L43,L44) -> 75 | N41: =L41-J41 -> 0 | O41: =IF(N41=0,"Yes","No") -> Yes
B42: A28 | C42: Project and technical documentation | D42: 7. Documentation, Presentation & Closure | E42: 7 | F42: =WORKDAY(Assumptions!$C$4-1,J42+1,Assumptions!$C$9:$C$14) -> 46414 | G42: =WORKDAY(Assumptions!$C$4-1,K42,Assumptions!$C$9:$C$14) -> 46422 | H42: M4 | I42: Project Manager, Business Analyst | J42: =MAX(K34) -> 59 | K42: =J42+E42 -> 66 | L42: =M42-E42 -> 68 | M42: =MIN(L44) -> 75 | N42: =L42-J42 -> 9 | O42: =IF(N42=0,"Yes","No") -> No
B43: A29 | C43: User training and handover sessions | D43: 7. Documentation, Presentation & Closure | E43: 3 | F43: =WORKDAY(Assumptions!$C$4-1,J43+1,Assumptions!$C$9:$C$14) -> 46436 | G43: =WORKDAY(Assumptions!$C$4-1,K43,Assumptions!$C$9:$C$14) -> 46440 | H43: M5 | I43: Business Analyst, Data Analyst | J43: =MAX(K41) -> 75 | K43: =J43+E43 -> 78 | L43: =M43-E43 -> 76 | M43: =MIN(L45) -> 79 | N43: =L43-J43 -> 1 | O43: =IF(N43=0,"Yes","No") -> No
B44: A30 | C44: Final business presentation preparation | D44: 7. Documentation, Presentation & Closure | E44: 4 | F44: =WORKDAY(Assumptions!$C$4-1,J44+1,Assumptions!$C$9:$C$14) -> 46436 | G44: =WORKDAY(Assumptions!$C$4-1,K44,Assumptions!$C$9:$C$14) -> 46441 | H44: M5, A28 | I44: Project Manager, Data Analyst | J44: =MAX(K41,K42) -> 75 | K44: =J44+E44 -> 79 | L44: =M44-E44 -> 75 | M44: =MIN(L45) -> 79 | N44: =L44-J44 -> 0 | O44: =IF(N44=0,"Yes","No") -> Yes
B45: A31 | C45: Final presentation to ShopSmart leadership | D45: 7. Documentation, Presentation & Closure | E45: 1 | F45: =WORKDAY(Assumptions!$C$4-1,J45+1,Assumptions!$C$9:$C$14) -> 46442 | G45: =WORKDAY(Assumptions!$C$4-1,K45,Assumptions!$C$9:$C$14) -> 46442 | H45: A29, A30 | I45: Project Manager | J45: =MAX(K43,K44) -> 79 | K45: =J45+E45 -> 80 | L45: =M45-E45 -> 79 | M45: =MIN(L46) -> 80 | N45: =L45-J45 -> 0 | O45: =IF(N45=0,"Yes","No") -> Yes
B46: A32 | C46: Project closure, lessons learned and repository finalisation | D46: 7. Documentation, Presentation & Closure | E46: 3 | F46: =WORKDAY(Assumptions!$C$4-1,J46+1,Assumptions!$C$9:$C$14) -> 46443 | G46: =WORKDAY(Assumptions!$C$4-1,K46,Assumptions!$C$9:$C$14) -> 46447 | H46: A31 | I46: Project Manager | J46: =MAX(K45) -> 80 | K46: =J46+E46 -> 83 | L46: =M46-E46 -> 80 | M46: =MIN(L47) -> 83 | N46: =L46-J46 -> 0 | O46: =IF(N46=0,"Yes","No") -> Yes
B47: M6 | C47: Milestone: Project Closed | D47: 7. Documentation, Presentation & Closure | E47: 0 | F47: =G47 -> 46447 | G47: =WORKDAY(Assumptions!$C$4-1,K47,Assumptions!$C$9:$C$14) -> 46447 | H47: A32 | I47: Project Manager | J47: =MAX(K46) -> 83 | K47: =J47+E47 -> 83 | L47: =M47-E47 -> 83 | M47: =MAX($K$5:$K$47) -> 83 | N47: =L47-J47 -> 0 | O47: =IF(N47=0,"Yes","No") -> Yes
C49: Total project duration (working days) | E49: =MAX(K5:K47) -> 83
...

Sheet Gantt Chart
B1: Gantt Chart (weekly view)
B4: ID | C4: Activity / Phase | D4: Start | E4: Finish | F4: Critical? | G4: Type | H4: Predecessors | I4: =Assumptions!$C$4 -> 46328 | J4: =I4+7 -> 46335 | K4: =J4+7 -> 46342 | L4: =K4+7 -> 46349 | M4: =L4+7 -> 46356 | N4: =M4+7 -> 46363 | O4: =N4+7 -> 46370 | P4: =O4+7 -> 46377 | Q4: =P4+7 -> 46384 | ... Z4: =Y4+7 -> 46447
B5: P1 | C5: INITIATION & MOBILISATION | D5: =MIN(D6:D9) -> 46328 | E5: =MAX(E6:E9) -> 46335 | G5: Phase | I5: =IF(AND($G5="Milestone",$D5>=I$4,$D5<=I$4+6),"◆","") | J5: =IF(AND($G5="Milestone",$D5>=J$4,$D5<=J$4+6),"◆","") | K5: =IF(AND($G5="Milestone",$D5>=K$4,$D5<=K$4+6),"◆","") | L5: =IF(AND($G5="Milestone",$D5>=L$4,$D5<=L$4+6),"◆","") | M5: =IF(AND($G5="Milestone",$D5>=M$4,$D5<=M$4+6),"◆","") | N5: =IF(AND($G5="Milestone",$D5>=N$4,$D5<=N$4+6),"◆","") | O5: =IF(AND($G5="Milestone",$D5>=O$4,$D5<=O$4+6),"◆","") | P5: =IF(AND($G5="Milestone",$D5>=P$4,$D5<=P$4+6),"◆","") | ... Z5: =IF(AND($G5="Milestone",$D5>=Z$4,$D5<=Z$4+6),"◆","")
B6: =Schedule!B5 -> A01 | C6: =Schedule!C5 -> Project kick-off and sign-off of execution plan | D6: =Schedule!F5 -> 46328 | E6: =Schedule!G5 -> 46329 | F6: =Schedule!O5 -> Yes | G6: Activity | H6: =Schedule!H5 -> None | I6: =IF(AND($G6="Milestone",$D6>=I$4,$D6<=I$4+6),"◆","") | J6: =IF(AND($G6="Milestone",$D6>=J$4,$D6<=J$4+6),"◆","") | K6: =IF(AND($G6="Milestone",$D6>=K$4,$D6<=K$4+6),"◆","") | L6: =IF(AND($G6="Milestone",$D6>=L$4,$D6<=L$4+6),"◆","") | M6: =IF(AND($G6="Milestone",$D6>=M$4,$D6<=M$4+6),"◆","") | N6: =IF(AND($G6="Milestone",$D6>=N$4,$D6<=N$4+6),"◆","") | O6: =IF(AND($G6="Milestone",$D6>=O$4,$D6<=O$4+6),"◆","") | P6: =IF(AND($G6="Milestone",$D6>=P$4,$D6<=P$4+6),"◆","") | ... Z6: =IF(AND($G6="Milestone",$D6>=Z$4,$D6<=Z$4+6),"◆","")
B7: =Schedule!B6 -> A02 | C7: =Schedule!C6 -> Tools, access and environment setup (Power BI, Python, GitHub, API keys) | D7: =Schedule!F6 -> 46330 | E7: =Schedule!G6 -> 46332 | F7: =Schedule!O6 -> No | G7: Activity | H7: =Schedule!H6 -> A01 | I7: =IF(AND($G7="Milestone",$D7>=I$4,$D7<=I$4+6),"◆","") | J7: =IF(AND($G7="Milestone",$D7>=J$4,$D7<=J$4+6),"◆","") | K7: =IF(AND($G7="Milestone",$D7>=K$4,$D7<=K$4+6),"◆","") | L7: =IF(AND($G7="Milestone",$D7>=L$4,$D7<=L$4+6),"◆","") | M7: =IF(AND($G7="Milestone",$D7>=M$4,$D7<=M$4+6),"◆","") | N7: =IF(AND($G7="Milestone",$D7>=N$4,$D7<=N$4+6),"◆","") | O7: =IF(AND($G7="Milestone",$D7>=O$4,$D7<=O$4+6),"◆","") | P7: =IF(AND($G7="Milestone",$D7>=P$4,$D7<=P$4+6),"◆","") | ... Z7: =IF(AND($G7="Milestone",$D7>=Z$4,$D7<=Z$4+6),"◆","")
B8: =Schedule!B7 -> A03 | C8: =Schedule!C7 -> Dataset handover and file validation (9 CSV files and data dictionary) | D8: =Schedule!F7 -> 46330 | E8: =Schedule!G7 -> 46335 | F8: =Schedule!O7 -> Yes | G8: Activity | H8: =Schedule!H7 -> A01 | I8: =IF(AND($G8="Milestone",$D8>=I$4,$D8<=I$4+6),"◆","") | J8: =IF(AND($G8="Milestone",$D8>=J$4,$D8<=J$4+6),"◆","") | K8: =IF(AND($G8="Milestone",$D8>=K$4,$D8<=K$4+6),"◆","") | L8: =IF(AND($G8="Milestone",$D8>=L$4,$D8<=L$4+6),"◆","") | M8: =IF(AND($G8="Milestone",$D8>=M$4,$D8<=M$4+6),"◆","") | N8: =IF(AND($G8="Milestone",$D8>=N$4,$D8<=N$4+6),"◆","") | O8: =IF(AND($G8="Milestone",$D8>=O$4,$D8<=O$4+6),"◆","") | P8: =IF(AND($G8="Milestone",$D8>=P$4,$D8<=P$4+6),"◆","") | ... Z8: =IF(AND($G8="Milestone",$D8>=Z$4,$D8<=Z$4+6),"◆","")
B9: =Schedule!B9 -> M1 | C9: =Schedule!C9 -> Milestone: Project Mobilised | D9: =Schedule!F9 -> 46335 | E9: =Schedule!G9 -> 46335 | F9: =Schedule!O9 -> Yes | G9: Milestone | H9: =Schedule!H9 -> A02, A03 | I9: =IF(AND($G9="Milestone",$D9>=I$4,$D9<=I$4+6),"◆","") | J9: =IF(AND($G9="Milestone",$D9>=J$4,$D9<=J$4+6),"◆","") -> ◆ | K9: =IF(AND($G9="Milestone",$D9>=K$4,$D9<=K$4+6),"◆","") | L9: =IF(AND($G9="Milestone",$D9>=L$4,$D9<=L$4+6),"◆","") | M9: =IF(AND($G9="Milestone",$D9>=M$4,$D9<=M$4+6),"◆","") | N9: =IF(AND($G9="Milestone",$D9>=N$4,$D9<=N$4+6),"◆","") | O9: =IF(AND($G9="Milestone",$D9>=O$4,$D9<=O$4+6),"◆","") | P9: =IF(AND($G9="Milestone",$D9>=P$4,$D9<=P$4+6),"◆","") | ... Z9: =IF(AND($G9="Milestone",$D9>=Z$4,$D9<=Z$4+6),"◆","")
B11: P2 | C11: DATA PREPARATION & REQUIREMENTS | D11: =MIN(D12:D16) -> 46336 | E11: =MAX(E12:E16) -> 46358 | G11: Phase | I11: =IF(AND($G11="Milestone",$D11>=I$4,$D11<=I$4+6),"◆","") | J11: =IF(AND($G11="Milestone",$D11>=J$4,$D11<=J$4+6),"◆","") | K11: =IF(AND($G11="Milestone",$D11>=K$4,$D11<=K$4+6),"◆","") | L11: =IF(AND($G11="Milestone",$D11>=L$4,$D11<=L$4+6),"◆","") | M11: =IF(AND($G11="Milestone",$D11>=M$4,$D11<=M$4+6),"◆","") | N11: =IF(AND($G11="Milestone",$D11>=N$4,$D11<=N$4+6),"◆","") | O11: =IF(AND($G11="Milestone",$D11>=O$4,$D11<=O$4+6),"◆","") | P11: =IF(AND($G11="Milestone",$D11>=P$4,$D11<=P$4+6),"◆","") | ... Z11: =IF(AND($G11="Milestone",$D11>=Z$4,$D11<=Z$4+6),"◆","")
B12: =Schedule!B10 -> A04 | C12: =Schedule!C10 -> Data profiling and quality assessment | D12: =Schedule!F10 -> 46336 | E12: =Schedule!G10 -> 46342 | F12: =Schedule!O10 -> Yes | G12: Activity | H12: =Schedule!H10 -> M1 | I12: =IF(AND($G12="Milestone",$D12>=I$4,$D12<=I$4+6),"◆","") | J12: =IF(AND($G12="Milestone",$D12>=J$4,$D12<=J$4+6),"◆","") | K12: =IF(AND($G12="Milestone",$D12>=K$4,$D12<=K$4+6),"◆","") | L12: =IF(AND($G12="Milestone",$D12>=L$4,$D12<=L$4+6),"◆","") | M12: =IF(AND($G12="Milestone",$D12>=M$4,$D12<=M$4+6),"◆","") | N12: =IF(AND($G12="Milestone",$D12>=N$4,$D12<=N$4+6),"◆","") | O12: =IF(AND($G12="Milestone",$D12>=O$4,$D12<=O$4+6),"◆","") | P12: =IF(AND($G12="Milestone",$D12>=P$4,$D12<=P$4+6),"◆","") | ... Z12: =IF(AND($G12="Milestone",$D12>=Z$4,$D12<=Z$4+6),"◆","")
B13: =Schedule!B11 -> A05 | C13: =Schedule!C11 -> Data cleaning and standardisation | D13: =Schedule!F11 -> 46343 | E13: =Schedule!G11 -> 46352 | F13: =Schedule!O11 -> Yes | G13: Activity | H13: =Schedule!H11 -> A04 | I13: =IF(AND($G13="Milestone",$D13>=I$4,$D13<=I$4+6),"◆","") | J13: =IF(AND($G13="Milestone",$D13>=J$4,$D13<=J$4+6),"◆","") | K13: =IF(AND($G13="Milestone",$D13>=K$4,$D13<=K$4+6),"◆","") | L13: =IF(AND($G13="Milestone",$D13>=L$4,$D13<=L$4+6),"◆","") | M13: =IF(AND($G13="Milestone",$D13>=M$4,$D13<=M$4+6),"◆","") | N13: =IF(AND($G13="Milestone",$D13>=N$4,$D13<=N$4+6),"◆","") | O13: =IF(AND($G13="Milestone",$D13>=O$4,$D13<=O$4+6),"◆","") | P13: =IF(AND($G13="Milestone",$D13>=P$4,$D13<=P$4+6),"◆","") | ... Z13: =IF(AND($G13="Milestone",$D13>=Z$4,$D13<=Z$4+6),"◆","")
B14: =Schedule!B12 -> A06 | C14: =Schedule!C12 -> Data validation and reconciliation checks | D14: =Schedule!F12 -> 46353 | E14: =Schedule!G12 -> 46358 | F14: =Schedule!O12 -> Yes | G14: Activity | H14: =Schedule!H12 -> A05 | I14: =IF(AND($G14="Milestone",$D14>=I$4,$D14<=I$4+6),"◆","") | J14: =IF(AND($G14="Milestone",$D14>=J$4,$D14<=J$4+6),"◆","") | K14: =IF(AND($G14="Milestone",$D14>=K$4,$D14<=K$4+6),"◆","") | L14: =IF(AND($G14="Milestone",$D14>=L$4,$D14<=L$4+6),"◆","") | M14: =IF(AND($G14="Milestone",$D14>=M$4,$D14<=M$4+6),"◆","") | N14: =IF(AND($G14="Milestone",$D14>=N$4,$D14<=N$4+6),"◆","") | O14: =IF(AND($G14="Milestone",$D14>=O$4,$D14<=O$4+6),"◆","") | P14: =IF(AND($G14="Milestone",$D14>=P$4,$D14<=P$4+6),"◆","") | ... Z14: =IF(AND($G14="Milestone",$D14>=Z$4,$D14<=Z$4+6),"◆","")
B15: =Schedule!B13 -> A07 | C15: =Schedule!C13 -> Requirements workshops with ShopSmart managers | D15: =Schedule!F13 -> 46336 | E15: =Schedule!G13 -> 46343 | F15: =Schedule!O13 -> No | G15: Activity | H15: =Schedule!H13 -> M1 | I15: =IF(AND($G15="Milestone",$D15>=I$4,$D15<=I$4+6),"◆","") | J15: =IF(AND($G15="Milestone",$D15>=J$4,$D15<=J$4+6),"◆","") | K15: =IF(AND($G15="Milestone",$D15>=K$4,$D15<=K$4+6),"◆","") | L15: =IF(AND($G15="Milestone",$D15>=L$4,$D15<=L$4+6),"◆","") | M15: =IF(AND($G15="Milestone",$D15>=M$4,$D15<=M$4+6),"◆","") | N15: =IF(AND($G15="Milestone",$D15>=N$4,$D15<=N$4+6),"◆","") | O15: =IF(AND($G15="Milestone",$D15>=O$4,$D15<=O$4+6),"◆","") | P15: =IF(AND($G15="Milestone",$D15>=P$4,$D15<=P$4+6),"◆","") | ... Z15: =IF(AND($G15="Milestone",$D15>=Z$4,$D15<=Z$4+6),"◆","")
B16: =Schedule!B15 -> M2 | C16: =Schedule!C15 -> Milestone: Clean Dataset and Requirements Baselined | D16: =Schedule!F15 -> 46358 | E16: =Schedule!G15 -> 46358 | F16: =Schedule!O15 -> Yes | G16: Milestone | H16: =Schedule!H15 -> A06, A07 | I16: =IF(AND($G16="Milestone",$D16>=I$4,$D16<=I$4+6),"◆","") | J16: =IF(AND($G16="Milestone",$D16>=J$4,$D16<=J$4+6),"◆","") | K16: =IF(AND($G16="Milestone",$D16>=K$4,$D16<=K$4+6),"◆","") | L16: =IF(AND($G16="Milestone",$D16>=L$4,$D16<=L$4+6),"◆","") | M16: =IF(AND($G16="Milestone",$D16>=M$4,$D16<=M$4+6),"◆","") -> ◆ | N16: =IF(AND($G16="Milestone",$D16>=N$4,$D16<=N$4+6),"◆","") | O16: =IF(AND($G16="Milestone",$D16>=O$4,$D16<=O$4+6),"◆","") | P16: =IF(AND($G16="Milestone",$D16>=P$4,$D16<=P$4+6),"◆","") | ... Z16: =IF(AND($G16="Milestone",$D16>=Z$4,$D16<=Z$4+6),"◆","")
B18: P3 | C18: DATA ANALYTICS & DATA SCIENCE | D18: =MIN(D19:D26) -> 46359 | E18: =MAX(E19:E26) -> 46386 | G18: Phase | I18: =IF(AND($G18="Milestone",$D18>=I$4,$D18<=I$4+6),"◆","") | J18: =IF(AND($G18="Milestone",$D18>=J$4,$D18<=J$4+6),"◆","") | K18: =IF(AND($G18="Milestone",$D18>=K$4,$D18<=K$4+6),"◆","") | L18: =IF(AND($G18="Milestone",$D18>=L$4,$D18<=L$4+6),"◆","") | M18: =IF(AND($G18="Milestone",$D18>=M$4,$D18<=M$4+6),"◆","") | N18: =IF(AND($G18="Milestone",$D18>=N$4,$D18<=N$4+6),"◆","") | O18: =IF(AND($G18="Milestone",$D18>=O$4,$D18<=O$4+6),"◆","") | P18: =IF(AND($G18="Milestone",$D18>=P$4,$D18<=P$4+6),"◆","") | ... Z18: =IF(AND($G18="Milestone",$D18>=Z$4,$D18<=Z$4+6),"◆","")
B19: =Schedule!B16 -> A08 | C19: =Schedule!C16 -> Exploratory data analysis and statistical insights | D19: =Schedule!F16 -> 46359 | E19: =Schedule!G16 -> 46367 | F19: =Schedule!O16 -> Yes | G19: Activity | H19: =Schedule!H16 -> M2 | I19: =IF(AND($G19="Milestone",$D19>=I$4,$D19<=I$4+6),"◆","") | J19: =IF(AND($G19="Milestone",$D19>=J$4,$D19<=J$4+6),"◆","") | K19: =IF(AND($G19="Milestone",$D19>=K$4,$D19<=K$4+6),"◆","") | L19: =IF(AND($G19="Milestone",$D19>=L$4,$D19<=L$4+6),"◆","") | M19: =IF(AND($G19="Milestone",$D19>=M$4,$D19<=M$4+6),"◆","") | N19: =IF(AND($G19="Milestone",$D19>=N$4,$D19<=N$4+6),"◆","") | O19: =IF(AND($G19="Milestone",$D19>=O$4,$D19<=O$4+6),"◆","") | P19: =IF(AND($G19="Milestone",$D19>=P$4,$D19<=P$4+6),"◆","") | ... Z19: =IF(AND($G19="Milestone",$D19>=Z$4,$D19<=Z$4+6),"◆","")
B20: =Schedule!B17 -> A09 | C20: =Schedule!C17 -> Sales dashboard development | D20: =Schedule!F17 -> 46359 | E20: =Schedule!G17 -> 46370 | F20: =Schedule!O17 -> No | G20: Activity | H20: =Schedule!H17 -> M2 | I20: =IF(AND($G20="Milestone",$D20>=I$4,$D20<=I$4+6),"◆","") | J20: =IF(AND($G20="Milestone",$D20>=J$4,$D20<=J$4+6),"◆","") | K20: =IF(AND($G20="Milestone",$D20>=K$4,$D20<=K$4+6),"◆","") | L20: =IF(AND($G20="Milestone",$D20>=L$4,$D20<=L$4+6),"◆","") | M20: =IF(AND($G20="Milestone",$D20>=M$4,$D20<=M$4+6),"◆","") | N20: =IF(AND($G20="Milestone",$D20>=N$4,$D20<=N$4+6),"◆","") | O20: =IF(AND($G20="Milestone",$D20>=O$4,$D20<=O$4+6),"◆","") | P20: =IF(AND($G20="Milestone",$D20>=P$4,$D20<=P$4+6),"◆","") | ... Z20: =IF(AND($G20="Milestone",$D20>=Z$4,$D20<=Z$4+6),"◆","")
B21: =Schedule!B18 -> A10 | C21: =Schedule!C18 -> Customer dashboard development | D21: =Schedule!F18 -> 46359 | E21: =Schedule!G18 -> 46367 | F21: =Schedule!O18 -> No | G21: Activity | H21: =Schedule!H18 -> M2 | I21: =IF(AND($G21="Milestone",$D21>=I$4,$D21<=I$4+6),"◆","") | J21: =IF(AND($G21="Milestone",$D21>=J$4,$D21<=J$4+6),"◆","") | K21: =IF(AND($G21="Milestone",$D21>=K$4,$D21<=K$4+6),"◆","") | L21: =IF(AND($G21="Milestone",$D21>=L$4,$D21<=L$4+6),"◆","") | M21: =IF(AND($G21="Milestone",$D21>=M$4,$D21<=M$4+6),"◆","") | N21: =IF(AND($G21="Milestone",$D21>=N$4,$D21<=N$4+6),"◆","") | O21: =IF(AND($G21="Milestone",$D21>=O$4,$D21<=O$4+6),"◆","") | P21: =IF(AND($G21="Milestone",$D21>=P$4,$D21<=P$4+6),"◆","") | ... Z21: =IF(AND($G21="Milestone",$D21>=Z$4,$D21<=Z$4+6),"◆","")
B22: =Schedule!B19 -> A11 | C22: =Schedule!C19 -> Store performance dashboard development | D22: =Schedule!F19 -> 46371 | E22: =Schedule!G19 -> 46378 | F22: =Schedule!O19 -> No | G22: Activity | H22: =Schedule!H19 -> A09 | I22: =IF(AND($G22="Milestone",$D22>=I$4,$D22<=I$4+6),"◆","") | J22: =IF(AND($G22="Milestone",$D22>=J$4,$D22<=J$4+6),"◆","") | K22: =IF(AND($G22="Milestone",$D22>=K$4,$D22<=K$4+6),"◆","") | L22: =IF(AND($G22="Milestone",$D22>=L$4,$D22<=L$4+6),"◆","") | M22: =IF(AND($G22="Milestone",$D22>=M$4,$D22<=M$4+6),"◆","") | N22: =IF(AND($G22="Milestone",$D22>=N$4,$D22<=N$4+6),"◆","") | O22: =IF(AND($G22="Milestone",$D22>=O$4,$D22<=O$4+6),"◆","") | P22: =IF(AND($G22="Milestone",$D22>=P$4,$D22<=P$4+6),"◆","") | ... Z22: =IF(AND($G22="Milestone",$D22>=Z$4,$D22<=Z$4+6),"◆","")
B23: =Schedule!B20 -> A12 | C23: =Schedule!C20 -> Inventory dashboard development | D23: =Schedule!F20 -> 46370 | E23: =Schedule!G20 -> 46377 | F23: =Schedule!O20 -> No | G23: Activity | H23: =Schedule!H20 -> A10 | I23: =IF(AND($G23="Milestone",$D23>=I$4,$D23<=I$4+6),"◆","") | J23: =IF(AND($G23="Milestone",$D23>=J$4,$D23<=J$4+6),"◆","") | K23: =IF(AND($G23="Milestone",$D23>=K$4,$D23<=K$4+6),"◆","") | L23: =IF(AND($G23="Milestone",$D23>=L$4,$D23<=L$4+6),"◆","") | M23: =IF(AND($G23="Milestone",$D23>=M$4,$D23<=M$4+6),"◆","") | N23: =IF(AND($G23="Milestone",$D23>=N$4,$D23<=N$4+6),"◆","") | O23: =IF(AND($G23="Milestone",$D23>=O$4,$D23<=O$4+6),"◆","") | P23: =IF(AND($G23="Milestone",$D23>=P$4,$D23<=P$4+6),"◆","") | ... Z23: =IF(AND($G23="Milestone",$D23>=Z$4,$D23<=Z$4+6),"◆","")
B24: =Schedule!B21 -> A13 | C24: =Schedule!C21 -> Executive analytics report | D24: =Schedule!F21 -> 46379 | E24: =Schedule!G21 -> 46386 | F24: =Schedule!O21 -> No | G24: Activity | H24: =Schedule!H21 -> A11, A12 | I24: =IF(AND($G24="Milestone",$D24>=I$4,$D24<=I$4+6),"◆","") | J24: =IF(AND($G24="Milestone",$D24>=J$4,$D24<=J$4+6),"◆","") | K24: =IF(AND($G24="Milestone",$D24>=K$4,$D24<=K$4+6),"◆","") | L24: =IF(AND($G24="Milestone",$D24>=L$4,$D24<=L$4+6),"◆","") | M24: =IF(AND($G24="Milestone",$D24>=M$4,$D24<=M$4+6),"◆","") | N24: =IF(AND($G24="Milestone",$D24>=N$4,$D24<=N$4+6),"◆","") | O24: =IF(AND($G24="Milestone",$D24>=O$4,$D24<=O$4+6),"◆","") | P24: =IF(AND($G24="Milestone",$D24>=P$4,$D24<=P$4+6),"◆","") | ... Z24: =IF(AND($G24="Milestone",$D24>=Z$4,$D24<=Z$4+6),"◆","")
B25: =Schedule!B22 -> A14 | C25: =Schedule!C22 -> Feature engineering pipeline | D25: =Schedule!F22 -> 46370 | E25: =Schedule!G22 -> 46379 | F25: =Schedule!O22 -> Yes | G25: Activity | H25: =Schedule!H22 -> A08 | I25: =IF(AND($G25="Milestone",$D25>=I$4,$D25<=I$4+6),"◆","") | J25: =IF(AND($G25="Milestone",$D25>=J$4,$D25<=J$4+6),"◆","") | K25: =IF(AND($G25="Milestone",$D25>=K$4,$D25<=K$4+6),"◆","") | L25: =IF(AND($G25="Milestone",$D25>=L$4,$D25<=L$4+6),"◆","") | M25: =IF(AND($G25="Milestone",$D25>=M$4,$D25<=M$4+6),"◆","") | N25: =IF(AND($G25="Milestone",$D25>=N$4,$D25<=N$4+6),"◆","") | O25: =IF(AND($G25="Milestone",$D25>=O$4,$D25<=O$4+6),"◆","") | P25: =IF(AND($G25="Milestone",$D25>=P$4,$D25<=P$4+6),"◆","") | ... Z25: =IF(AND($G25="Milestone",$D25>=Z$4,$D25<=Z$4+6),"◆","")
B26: =Schedule!B24 -> M3 | C26: =Schedule!C24 -> Milestone: Analytics and Feature Pipeline Complete | D26: =Schedule!F24 -> 46386 | E26: =Schedule!G24 -> 46386 | F26: =Schedule!O24 -> No | G26: Milestone | H26: =Schedule!H24 -> A13, A14 | I26: =IF(AND($G26="Milestone",$D26>=I$4,$D26<=I$4+6),"◆","") | J26: =IF(AND($G26="Milestone",$D26>=J$4,$D26<=J$4+6),"◆","") | K26: =IF(AND($G26="Milestone",$D26>=K$4,$D26<=K$4+6),"◆","") | L26: =IF(AND($G26="Milestone",$D26>=L$4,$D26<=L$4+6),"◆","") | M26: =IF(AND($G26="Milestone",$D26>=M$4,$D26<=M$4+6),"◆","") | N26: =IF(AND($G26="Milestone",$D26>=N$4,$D26<=N$4+6),"◆","") | O26: =IF(AND($G26="Milestone",$D26>=O$4,$D26<=O$4+6),"◆","") | P26: =IF(AND($G26="Milestone",$D26>=P$4,$D26<=P$4+6),"◆","") | ... Z26: =IF(AND($G26="Milestone",$D26>=Z$4,$D26<=Z$4+6),"◆","")
B28: P4 | C28: MACHINE LEARNING | D28: =MIN(D29:D32) -> 46380 | E28: =MAX(E29:E32) -> 46413 | G28: Phase | I28: =IF(AND($G28="Milestone",$D28>=I$4,$D28<=I$4+6),"◆","") | J28: =IF(AND($G28="Milestone",$D28>=J$4,$D28<=J$4+6),"◆","") | K28: =IF(AND($G28="Milestone",$D28>=K$4,$D28<=K$4+6),"◆","") | L28: =IF(AND($G28="Milestone",$D28>=L$4,$D28<=L$4+6),"◆","") | M28: =IF(AND($G28="Milestone",$D28>=M$4,$D28<=M$4+6),"◆","") | N28: =IF(AND($G28="Milestone",$D28>=N$4,$D28<=N$4+6),"◆","") | O28: =IF(AND($G28="Milestone",$D28>=O$4,$D28<=O$4+6),"◆","") | P28: =IF(AND($G28="Milestone",$D28>=P$4,$D28<=P$4+6),"◆","") | ... Z28: =IF(AND($G28="Milestone",$D28>=Z$4,$D28<=Z$4+6),"◆","")
B29: =Schedule!B25 -> A15 | C29: =Schedule!C25 -> Sales forecasting model development | D29: =Schedule!F25 -> 46380 | E29: =Schedule!G25 -> 46400 | F29: =Schedule!O25 -> No | G29: Activity | H29: =Schedule!H25 -> A14 | I29: =IF(AND($G29="Milestone",$D29>=I$4,$D29<=I$4+6),"◆","") | J29: =IF(AND($G29="Milestone",$D29>=J$4,$D29<=J$4+6),"◆","") | K29: =IF(AND($G29="Milestone",$D29>=K$4,$D29<=K$4+6),"◆","") | L29: =IF(AND($G29="Milestone",$D29>=L$4,$D29<=L$4+6),"◆","") | M29: =IF(AND($G29="Milestone",$D29>=M$4,$D29<=M$4+6),"◆","") | N29: =IF(AND($G29="Milestone",$D29>=N$4,$D29<=N$4+6),"◆","") | O29: =IF(AND($G29="Milestone",$D29>=O$4,$D29<=O$4+6),"◆","") | P29: =IF(AND($G29="Milestone",$D29>=P$4,$D29<=P$4+6),"◆","") | ... Z29: =IF(AND($G29="Milestone",$D29>=Z$4,$D29<=Z$4+6),"◆","")
B30: =Schedule!B26 -> A16 | C30: =Schedule!C26 -> Customer segmentation model | D30: =Schedule!F26 -> 46380 | E30: =Schedule!G26 -> 46394 | F30: =Schedule!O26 -> Yes | G30: Activity | H30: =Schedule!H26 -> A14 | I30: =IF(AND($G30="Milestone",$D30>=I$4,$D30<=I$4+6),"◆","") | J30: =IF(AND($G30="Milestone",$D30>=J$4,$D30<=J$4+6),"◆","") | K30: =IF(AND($G30="Milestone",$D30>=K$4,$D30<=K$4+6),"◆","") | L30: =IF(AND($G30="Milestone",$D30>=L$4,$D30<=L$4+6),"◆","") | M30: =IF(AND($G30="Milestone",$D30>=M$4,$D30<=M$4+6),"◆","") | N30: =IF(AND($G30="Milestone",$D30>=N$4,$D30<=N$4+6),"◆","") | O30: =IF(AND($G30="Milestone",$D30>=O$4,$D30<=O$4+6),"◆","") | P30: =IF(AND($G30="Milestone",$D30>=P$4,$D30<=P$4+6),"◆","") | ... Z30: =IF(AND($G30="Milestone",$D30>=Z$4,$D30<=Z$4+6),"◆","")
B31: =Schedule!B27 -> A17 | C31: =Schedule!C27 -> Product recommendation prototype | D31: =Schedule!F27 -> 46395 | E31: =Schedule!G27 -> 46406 | F31: =Schedule!O27 -> Yes | G31: Activity | H31: =Schedule!H27 -> A16 | I31: =IF(AND($G31="Milestone",$D31>=I$4,$D31<=I$4+6),"◆","") | J31: =IF(AND($G31="Milestone",$D31>=J$4,$D31<=J$4+6),"◆","") | K31: =IF(AND($G31="Milestone",$D31>=K$4,$D31<=K$4+6),"◆","") | L31: =IF(AND($G31="Milestone",$D31>=L$4,$D31<=L$4+6),"◆","") | M31: =IF(AND($G31="Milestone",$D31>=M$4,$D31<=M$4+6),"◆","") | N31: =IF(AND($G31="Milestone",$D31>=N$4,$D31<=N$4+6),"◆","") | O31: =IF(AND($G31="Milestone",$D31>=O$4,$D31<=O$4+6),"◆","") | P31: =IF(AND($G31="Milestone",$D31>=P$4,$D31<=P$4+6),"◆","") | ... Z31: =IF(AND($G31="Milestone",$D31>=Z$4,$D31<=Z$4+6),"◆","")
B32: =Schedule!B28 -> A18 | C32: =Schedule!C28 -> Model evaluation and evaluation report | D32: =Schedule!F28 -> 46407 | E32: =Schedule!G28 -> 46413 | F32: =Schedule!O28 -> Yes | G32: Activity | H32: =Schedule!H28 -> A15, A17 | I32: =IF(AND($G32="Milestone",$D32>=I$4,$D32<=I$4+6),"◆","") | J32: =IF(AND($G32="Milestone",$D32>=J$4,$D32<=J$4+6),"◆","") | K32: =IF(AND($G32="Milestone",$D32>=K$4,$D32<=K$4+6),"◆","") | L32: =IF(AND($G32="Milestone",$D32>=L$4,$D32<=L$4+6),"◆","") | M32: =IF(AND($G32="Milestone",$D32>=M$4,$D32<=M$4+6),"◆","") | N32: =IF(AND($G32="Milestone",$D32>=N$4,$D32<=N$4+6),"◆","") | O32: =IF(AND($G32="Milestone",$D32>=O$4,$D32<=O$4+6),"◆","") | P32: =IF(AND($G32="Milestone",$D32>=P$4,$D32<=P$4+6),"◆","") | ... Z32: =IF(AND($G32="Milestone",$D32>=Z$4,$D32<=Z$4+6),"◆","")
B34: P5 | C34: GENERATIVE AI | D34: =MIN(D35:D38) -> 46359 | E34: =MAX(E35:E38) -> 46407 | G34: Phase | I34: =IF(AND($G34="Milestone",$D34>=I$4,$D34<=I$4+6),"◆","") | J34: =IF(AND($G34="Milestone",$D34>=J$4,$D34<=J$4+6),"◆","") | K34: =IF(AND($G34="Milestone",$D34>=K$4,$D34<=K$4+6),"◆","") | L34: =IF(AND($G34="Milestone",$D34>=L$4,$D34<=L$4+6),"◆","") | M34: =IF(AND($G34="Milestone",$D34>=M$4,$D34<=M$4+6),"◆","") | N34: =IF(AND($G34="Milestone",$D34>=N$4,$D34<=N$4+6),"◆","") | O34: =IF(AND($G34="Milestone",$D34>=O$4,$D34<=O$4+6),"◆","") | P34: =IF(AND($G34="Milestone",$D34>=P$4,$D34<=P$4+6),"◆","") | ... Z34: =IF(AND($G34="Milestone",$D34>=Z$4,$D34<=Z$4+6),"◆","")
B35: =Schedule!B29 -> A19 | C35: =Schedule!C29 -> Prompt library design and testing | D35: =Schedule!F29 -> 46359 | E35: =Schedule!G29 -> 46370 | F35: =Schedule!O29 -> No | G35: Activity | H35: =Schedule!H29 -> M2 | I35: =IF(AND($G35="Milestone",$D35>=I$4,$D35<=I$4+6),"◆","") | J35: =IF(AND($G35="Milestone",$D35>=J$4,$D35<=J$4+6),"◆","") | K35: =IF(AND($G35="Milestone",$D35>=K$4,$D35<=K$4+6),"◆","") | L35: =IF(AND($G35="Milestone",$D35>=L$4,$D35<=L$4+6),"◆","") | M35: =IF(AND($G35="Milestone",$D35>=M$4,$D35<=M$4+6),"◆","") | N35: =IF(AND($G35="Milestone",$D35>=N$4,$D35<=N$4+6),"◆","") | O35: =IF(AND($G35="Milestone",$D35>=O$4,$D35<=O$4+6),"◆","") | P35: =IF(AND($G35="Milestone",$D35>=P$4,$D35<=P$4+6),"◆","") | ... Z35: =IF(AND($G35="Milestone",$D35>=Z$4,$D35<=Z$4+6),"◆","")
B36: =Schedule!B30 -> A20 | C36: =Schedule!C30 -> Retail report generator | D36: =Schedule!F30 -> 46371 | E36: =Schedule!G30 -> 46379 | F36: =Schedule!O30 -> No | G36: Activity | H36: =Schedule!H30 -> A19 | I36: =IF(AND($G36="Milestone",$D36>=I$4,$D36<=I$4+6),"◆","") | J36: =IF(AND($G36="Milestone",$D36>=J$4,$D36<=J$4+6),"◆","") | K36: =IF(AND($G36="Milestone",$D36>=K$4,$D36<=K$4+6),"◆","") | L36: =IF(AND($G36="Milestone",$D36>=L$4,$D36<=L$4+6),"◆","") | M36: =IF(AND($G36="Milestone",$D36>=M$4,$D36<=M$4+6),"◆","") | N36: =IF(AND($G36="Milestone",$D36>=N$4,$D36<=N$4+6),"◆","") | O36: =IF(AND($G36="Milestone",$D36>=O$4,$D36<=O$4+6),"◆","") | P36: =IF(AND($G36="Milestone",$D36>=P$4,$D36<=P$4+6),"◆","") | ... Z36: =IF(AND($G36="Milestone",$D36>=Z$4,$D36<=Z$4+6),"◆","")
B37: =Schedule!B31 -> A21 | C37: =Schedule!C31 -> AI Retail Copilot development (Streamlit) | D37: =Schedule!F31 -> 46380 | E37: =Schedule!G31 -> 46400 | F37: =Schedule!O31 -> No | G37: Activity | H37: =Schedule!H31 -> A20 | I37: =IF(AND($G37="Milestone",$D37>=I$4,$D37<=I$4+6),"◆","") | J37: =IF(AND($G37="Milestone",$D37>=J$4,$D37<=J$4+6),"◆","") | K37: =IF(AND($G37="Milestone",$D37>=K$4,$D37<=K$4+6),"◆","") | L37: =IF(AND($G37="Milestone",$D37>=L$4,$D37<=L$4+6),"◆","") | M37: =IF(AND($G37="Milestone",$D37>=M$4,$D37<=M$4+6),"◆","") | N37: =IF(AND($G37="Milestone",$D37>=N$4,$D37<=N$4+6),"◆","") | O37: =IF(AND($G37="Milestone",$D37>=O$4,$D37<=O$4+6),"◆","") | P37: =IF(AND($G37="Milestone",$D37>=P$4,$D37<=P$4+6),"◆","") | ... Z37: =IF(AND($G37="Milestone",$D37>=Z$4,$D37<=Z$4+6),"◆","")
B38: =Schedule!B32 -> A22 | C38: =Schedule!C32 -> Copilot integration with data and forecasting model | D38: =Schedule!F32 -> 46401 | E38: =Schedule!G32 -> 46407 | F38: =Schedule!O32 -> No | G38: Activity | H38: =Schedule!H32 -> A21, A15 | I38: =IF(AND($G38="Milestone",$D38>=I$4,$D38<=I$4+6),"◆","") | J38: =IF(AND($G38="Milestone",$D38>=J$4,$D38<=J$4+6),"◆","") | K38: =IF(AND($G38="Milestone",$D38>=K$4,$D38<=K$4+6),"◆","") | L38: =IF(AND($G38="Milestone",$D38>=L$4,$D38<=L$4+6),"◆","") | M38: =IF(AND($G38="Milestone",$D38>=M$4,$D38<=M$4+6),"◆","") | N38: =IF(AND($G38="Milestone",$D38>=N$4,$D38<=N$4+6),"◆","") | O38: =IF(AND($G38="Milestone",$D38>=O$4,$D38<=O$4+6),"◆","") | P38: =IF(AND($G38="Milestone",$D38>=P$4,$D38<=P$4+6),"◆","") | ... Z38: =IF(AND($G38="Milestone",$D38>=Z$4,$D38<=Z$4+6),"◆","")
B40: P6 | C40: TESTING & QUALITY ASSURANCE | D40: =MIN(D41:D47) -> 46413 | E40: =MAX(E41:E47) -> 46435 | G40: Phase | I40: =IF(AND($G40="Milestone",$D40>=I$4,$D40<=I$4+6),"◆","") | J40: =IF(AND($G40="Milestone",$D40>=J$4,$D40<=J$4+6),"◆","") | K40: =IF(AND($G40="Milestone",$D40>=K$4,$D40<=K$4+6),"◆","") | L40: =IF(AND($G40="Milestone",$D40>=L$4,$D40<=L$4+6),"◆","") | M40: =IF(AND($G40="Milestone",$D40>=M$4,$D40<=M$4+6),"◆","") | N40: =IF(AND($G40="Milestone",$D40>=N$4,$D40<=N$4+6),"◆","") | O40: =IF(AND($G40="Milestone",$D40>=O$4,$D40<=O$4+6),"◆","") | P40: =IF(AND($G40="Milestone",$D40>=P$4,$D40<=P$4+6),"◆","") | ... Z40: =IF(AND($G40="Milestone",$D40>=Z$4,$D40<=Z$4+6),"◆","")
B41: =Schedule!B34 -> M4 | C41: =Schedule!C34 -> Milestone: All Workstream Deliverables Built | D41: =Schedule!F34 -> 46413 | E41: =Schedule!G34 -> 46413 | F41: =Schedule!O34 -> Yes | G41: Milestone | H41: =Schedule!H34 -> A18, A22, M3 | I41: =IF(AND($G41="Milestone",$D41>=I$4,$D41<=I$4+6),"◆","") | J41: =IF(AND($G41="Milestone",$D41>=J$4,$D41<=J$4+6),"◆","") | K41: =IF(AND($G41="Milestone",$D41>=K$4,$D41<=K$4+6),"◆","") | L41: =IF(AND($G41="Milestone",$D41>=L$4,$D41<=L$4+6),"◆","") | M41: =IF(AND($G41="Milestone",$D41>=M$4,$D41<=M$4+6),"◆","") | N41: =IF(AND($G41="Milestone",$D41>=N$4,$D41<=N$4+6),"◆","") | O41: =IF(AND($G41="Milestone",$D41>=O$4,$D41<=O$4+6),"◆","") | P41: =IF(AND($G41="Milestone",$D41>=P$4,$D41<=P$4+6),"◆","") | ... Z41: =IF(AND($G41="Milestone",$D41>=Z$4,$D41<=Z$4+6),"◆","")
B42: =Schedule!B35 -> A23 | C42: =Schedule!C35 -> Dashboard quality review and data accuracy testing | D42: =Schedule!F35 -> 46414 | E42: =Schedule!G35 -> 46419 | F42: =Schedule!O35 -> No | G42: Activity | H42: =Schedule!H35 -> M4 | I42: =IF(AND($G42="Milestone",$D42>=I$4,$D42<=I$4+6),"◆","") | J42: =IF(AND($G42="Milestone",$D42>=J$4,$D42<=J$4+6),"◆","") | K42: =IF(AND($G42="Milestone",$D42>=K$4,$D42<=K$4+6),"◆","") | L42: =IF(AND($G42="Milestone",$D42>=L$4,$D42<=L$4+6),"◆","") | M42: =IF(AND($G42="Milestone",$D42>=M$4,$D42<=M$4+6),"◆","") | N42: =IF(AND($G42="Milestone",$D42>=N$4,$D42<=N$4+6),"◆","") | O42: =IF(AND($G42="Milestone",$D42>=O$4,$D42<=O$4+6),"◆","") | P42: =IF(AND($G42="Milestone",$D42>=P$4,$D42<=P$4+6),"◆","") | ... Z42: =IF(AND($G42="Milestone",$D42>=Z$4,$D42<=Z$4+6),"◆","")
B43: =Schedule!B36 -> A24 | C43: =Schedule!C36 -> Code review and model testing | D43: =Schedule!F36 -> 46414 | E43: =Schedule!G36 -> 46420 | F43: =Schedule!O36 -> No | G43: Activity | H43: =Schedule!H36 -> M4 | I43: =IF(AND($G43="Milestone",$D43>=I$4,$D43<=I$4+6),"◆","") | J43: =IF(AND($G43="Milestone",$D43>=J$4,$D43<=J$4+6),"◆","") | K43: =IF(AND($G43="Milestone",$D43>=K$4,$D43<=K$4+6),"◆","") | L43: =IF(AND($G43="Milestone",$D43>=L$4,$D43<=L$4+6),"◆","") | M43: =IF(AND($G43="Milestone",$D43>=M$4,$D43<=M$4+6),"◆","") | N43: =IF(AND($G43="Milestone",$D43>=N$4,$D43<=N$4+6),"◆","") | O43: =IF(AND($G43="Milestone",$D43>=O$4,$D43<=O$4+6),"◆","") | P43: =IF(AND($G43="Milestone",$D43>=P$4,$D43<=P$4+6),"◆","") | ... Z43: =IF(AND($G43="Milestone",$D43>=Z$4,$D43<=Z$4+6),"◆","")
B44: =Schedule!B37 -> A25 | C44: =Schedule!C37 -> Copilot testing and prompt evaluation | D44: =Schedule!F37 -> 46414 | E44: =Schedule!G37 -> 46421 | F44: =Schedule!O37 -> Yes | G44: Activity | H44: =Schedule!H37 -> M4 | I44: =IF(AND($G44="Milestone",$D44>=I$4,$D44<=I$4+6),"◆","") | J44: =IF(AND($G44="Milestone",$D44>=J$4,$D44<=J$4+6),"◆","") | K44: =IF(AND($G44="Milestone",$D44>=K$4,$D44<=K$4+6),"◆","") | L44: =IF(AND($G44="Milestone",$D44>=L$4,$D44<=L$4+6),"◆","") | M44: =IF(AND($G44="Milestone",$D44>=M$4,$D44<=M$4+6),"◆","") | N44: =IF(AND($G44="Milestone",$D44>=N$4,$D44<=N$4+6),"◆","") | O44: =IF(AND($G44="Milestone",$D44>=O$4,$D44<=O$4+6),"◆","") | P44: =IF(AND($G44="Milestone",$D44>=P$4,$D44<=P$4+6),"◆","") | ... Z44: =IF(AND($G44="Milestone",$D44>=Z$4,$D44<=Z$4+6),"◆","")
B45: =Schedule!B38 -> A26 | C45: =Schedule!C38 -> User acceptance testing with ShopSmart managers | D45: =Schedule!F38 -> 46422 | E45: =Schedule!G38 -> 46428 | F45: =Schedule!O38 -> Yes | G45: Activity | H45: =Schedule!H38 -> A23, A24, A25 | I45: =IF(AND($G45="Milestone",$D45>=I$4,$D45<=I$4+6),"◆","") | J45: =IF(AND($G45="Milestone",$D45>=J$4,$D45<=J$4+6),"◆","") | K45: =IF(AND($G45="Milestone",$D45>=K$4,$D45<=K$4+6),"◆","") | L45: =IF(AND($G45="Milestone",$D45>=L$4,$D45<=L$4+6),"◆","") | M45: =IF(AND($G45="Milestone",$D45>=M$4,$D45<=M$4+6),"◆","") | N45: =IF(AND($G45="Milestone",$D45>=N$4,$D45<=N$4+6),"◆","") | O45: =IF(AND($G45="Milestone",$D45>=O$4,$D45<=O$4+6),"◆","") | P45: =IF(AND($G45="Milestone",$D45>=P$4,$D45<=P$4+6),"◆","") | ... Z45: =IF(AND($G45="Milestone",$D45>=Z$4,$D45<=Z$4+6),"◆","")
B46: =Schedule!B39 -> A27 | C46: =Schedule!C39 -> Defect fixing and retesting | D46: =Schedule!F39 -> 46429 | E46: =Schedule!G39 -> 46435 | F46: =Schedule!O39 -> Yes | G46: Activity | H46: =Schedule!H39 -> A26 | I46: =IF(AND($G46="Milestone",$D46>=I$4,$D46<=I$4+6),"◆","") | J46: =IF(AND($G46="Milestone",$D46>=J$4,$D46<=J$4+6),"◆","") | K46: =IF(AND($G46="Milestone",$D46>=K$4,$D46<=K$4+6),"◆","") | L46: =IF(AND($G46="Milestone",$D46>=L$4,$D46<=L$4+6),"◆","") | M46: =IF(AND($G46="Milestone",$D46>=M$4,$D46<=M$4+6),"◆","") | N46: =IF(AND($G46="Milestone",$D46>=N$4,$D46<=N$4+6),"◆","") | O46: =IF(AND($G46="Milestone",$D46>=O$4,$D46<=O$4+6),"◆","") | P46: =IF(AND($G46="Milestone",$D46>=P$4,$D46<=P$4+6),"◆","") | ... Z46: =IF(AND($G46="Milestone",$D46>=Z$4,$D46<=Z$4+6),"◆","")
B47: =Schedule!B41 -> M5 | C47: =Schedule!C41 -> Milestone: Deliverables Accepted | D47: =Schedule!F41 -> 46435 | E47: =Schedule!G41 -> 46435 | F47: =Schedule!O41 -> Yes | G47: Milestone | H47: =Schedule!H41 -> A27 | I47: =IF(AND($G47="Milestone",$D47>=I$4,$D47<=I$4+6),"◆","") | J47: =IF(AND($G47="Milestone",$D47>=J$4,$D47<=J$4+6),"◆","") | K47: =IF(AND($G47="Milestone",$D47>=K$4,$D47<=K$4+6),"◆","") | L47: =IF(AND($G47="Milestone",$D47>=L$4,$D47<=L$4+6),"◆","") | M47: =IF(AND($G47="Milestone",$D47>=M$4,$D47<=M$4+6),"◆","") | N47: =IF(AND($G47="Milestone",$D47>=N$4,$D47<=N$4+6),"◆","") | O47: =IF(AND($G47="Milestone",$D47>=O$4,$D47<=O$4+6),"◆","") | P47: =IF(AND($G47="Milestone",$D47>=P$4,$D47<=P$4+6),"◆","") | ... Z47: =IF(AND($G47="Milestone",$D47>=Z$4,$D47<=Z$4+6),"◆","")
...

Sheet Critical Path
B1: Critical Path Analysis
B4: Total project duration (working days) | D4: =MAX(Schedule!K5:K47) -> 83
B5: Project start date | D5: =Assumptions!$C$4 -> 46328
B6: Project finish date | D6: =MAX(Schedule!G5:G47) -> 46447
B7: Critical activities (excluding milestones) | D7: =COUNTIFS(Schedule!O5:O47,"Yes",Schedule!E5:E47,">0") -> 16
B8: Activities with float | D8: =COUNTIFS(Schedule!N5:N47,">0",Schedule!E5:E47,">0") -> 16
B10: Table 1: Critical path (zero float), in sequence
B11: ID | C11: Activity | D11: Duration | E11: Start | F11: Finish | G11: Float
B12: A01 | C12: {=INDEX(Schedule!$C$5:$C$47,MATCH($B12,Schedule!$B$5:$B$47,0))} -> Project kick-off and sign-off of execution plan | D12: {=INDEX(Schedule!$E$5:$E$47,MATCH($B12,Schedule!$B$5:$B$47,0))} -> 2 | E12: {=INDEX(Schedule!$F$5:$F$47,MATCH($B12,Schedule!$B$5:$B$47,0))} -> 46328 | F12: {=INDEX(Schedule!$G$5:$G$47,MATCH($B12,Schedule!$B$5:$B$47,0))} -> 46329 | G12: {=INDEX(Schedule!$N$5:$N$47,MATCH($B12,Schedule!$B$5:$B$47,0))} -> 0
B13: A03 | C13: {=INDEX(Schedule!$C$5:$C$47,MATCH($B13,Schedule!$B$5:$B$47,0))} -> Dataset handover and file validation (9 CSV files and data dictionary) | D13: {=INDEX(Schedule!$E$5:$E$47,MATCH($B13,Schedule!$B$5:$B$47,0))} -> 4 | E13: {=INDEX(Schedule!$F$5:$F$47,MATCH($B13,Schedule!$B$5:$B$47,0))} -> 46330 | F13: {=INDEX(Schedule!$G$5:$G$47,MATCH($B13,Schedule!$B$5:$B$47,0))} -> 46335 | G13: {=INDEX(Schedule!$N$5:$N$47,MATCH($B13,Schedule!$B$5:$B$47,0))} -> 0
B15: M1 | C15: {=INDEX(Schedule!$C$5:$C$47,MATCH($B15,Schedule!$B$5:$B$47,0))} -> Milestone: Project Mobilised | D15: {=INDEX(Schedule!$E$5:$E$47,MATCH($B15,Schedule!$B$5:$B$47,0))} -> 0 | E15: {=INDEX(Schedule!$F$5:$F$47,MATCH($B15,Schedule!$B$5:$B$47,0))} -> 46335 | F15: {=INDEX(Schedule!$G$5:$G$47,MATCH($B15,Schedule!$B$5:$B$47,0))} -> 46335 | G15: {=INDEX(Schedule!$N$5:$N$47,MATCH($B15,Schedule!$B$5:$B$47,0))} -> 0
B16: A04 | C16: {=INDEX(Schedule!$C$5:$C$47,MATCH($B16,Schedule!$B$5:$B$47,0))} -> Data profiling and quality assessment | D16: {=INDEX(Schedule!$E$5:$E$47,MATCH($B16,Schedule!$B$5:$B$47,0))} -> 5 | E16: {=INDEX(Schedule!$F$5:$F$47,MATCH($B16,Schedule!$B$5:$B$47,0))} -> 46336 | F16: {=INDEX(Schedule!$G$5:$G$47,MATCH($B16,Schedule!$B$5:$B$47,0))} -> 46342 | G16: {=INDEX(Schedule!$N$5:$N$47,MATCH($B16,Schedule!$B$5:$B$47,0))} -> 0
B17: A05 | C17: {=INDEX(Schedule!$C$5:$C$47,MATCH($B17,Schedule!$B$5:$B$47,0))} -> Data cleaning and standardisation | D17: {=INDEX(Schedule!$E$5:$E$47,MATCH($B17,Schedule!$B$5:$B$47,0))} -> 8 | E17: {=INDEX(Schedule!$F$5:$F$47,MATCH($B17,Schedule!$B$5:$B$47,0))} -> 46343 | F17: {=INDEX(Schedule!$G$5:$G$47,MATCH($B17,Schedule!$B$5:$B$47,0))} -> 46352 | G17: {=INDEX(Schedule!$N$5:$N$47,MATCH($B17,Schedule!$B$5:$B$47,0))} -> 0
B18: A06 | C18: {=INDEX(Schedule!$C$5:$C$47,MATCH($B18,Schedule!$B$5:$B$47,0))} -> Data validation and reconciliation checks | D18: {=INDEX(Schedule!$E$5:$E$47,MATCH($B18,Schedule!$B$5:$B$47,0))} -> 4 | E18: {=INDEX(Schedule!$F$5:$F$47,MATCH($B18,Schedule!$B$5:$B$47,0))} -> 46353 | F18: {=INDEX(Schedule!$G$5:$G$47,MATCH($B18,Schedule!$B$5:$B$47,0))} -> 46358 | G18: {=INDEX(Schedule!$N$5:$N$47,MATCH($B18,Schedule!$B$5:$B$47,0))} -> 0
B20: M2 | C20: {=INDEX(Schedule!$C$5:$C$47,MATCH($B20,Schedule!$B$5:$B$47,0))} -> Milestone: Clean Dataset and Requirements Baselined | D20: {=INDEX(Schedule!$E$5:$E$47,MATCH($B20,Schedule!$B$5:$B$47,0))} -> 0 | E20: {=INDEX(Schedule!$F$5:$F$47,MATCH($B20,Schedule!$B$5:$B$47,0))} -> 46358 | F20: {=INDEX(Schedule!$G$5:$G$47,MATCH($B20,Schedule!$B$5:$B$47,0))} -> 46358 | G20: {=INDEX(Schedule!$N$5:$N$47,MATCH($B20,Schedule!$B$5:$B$47,0))} -> 0
B21: A08 | C21: {=INDEX(Schedule!$C$5:$C$47,MATCH($B21,Schedule!$B$5:$B$47,0))} -> Exploratory data analysis and statistical insights | D21: {=INDEX(Schedule!$E$5:$E$47,MATCH($B21,Schedule!$B$5:$B$47,0))} -> 7 | E21: {=INDEX(Schedule!$F$5:$F$47,MATCH($B21,Schedule!$B$5:$B$47,0))} -> 46359 | F21: {=INDEX(Schedule!$G$5:$G$47,MATCH($B21,Schedule!$B$5:$B$47,0))} -> 46367 | G21: {=INDEX(Schedule!$N$5:$N$47,MATCH($B21,Schedule!$B$5:$B$47,0))} -> 0
B22: A14 | C22: {=INDEX(Schedule!$C$5:$C$47,MATCH($B22,Schedule!$B$5:$B$47,0))} -> Feature engineering pipeline | D22: {=INDEX(Schedule!$E$5:$E$47,MATCH($B22,Schedule!$B$5:$B$47,0))} -> 8 | E22: {=INDEX(Schedule!$F$5:$F$47,MATCH($B22,Schedule!$B$5:$B$47,0))} -> 46370 | F22: {=INDEX(Schedule!$G$5:$G$47,MATCH($B22,Schedule!$B$5:$B$47,0))} -> 46379 | G22: {=INDEX(Schedule!$N$5:$N$47,MATCH($B22,Schedule!$B$5:$B$47,0))} -> 0
B23: A16 | C23: {=INDEX(Schedule!$C$5:$C$47,MATCH($B23,Schedule!$B$5:$B$47,0))} -> Customer segmentation model | D23: {=INDEX(Schedule!$E$5:$E$47,MATCH($B23,Schedule!$B$5:$B$47,0))} -> 8 | E23: {=INDEX(Schedule!$F$5:$F$47,MATCH($B23,Schedule!$B$5:$B$47,0))} -> 46380 | F23: {=INDEX(Schedule!$G$5:$G$47,MATCH($B23,Schedule!$B$5:$B$47,0))} -> 46394 | G23: {=INDEX(Schedule!$N$5:$N$47,MATCH($B23,Schedule!$B$5:$B$47,0))} -> 0
B24: A17 | C24: {=INDEX(Schedule!$C$5:$C$47,MATCH($B24,Schedule!$B$5:$B$47,0))} -> Product recommendation prototype | D24: {=INDEX(Schedule!$E$5:$E$47,MATCH($B24,Schedule!$B$5:$B$47,0))} -> 8 | E24: {=INDEX(Schedule!$F$5:$F$47,MATCH($B24,Schedule!$B$5:$B$47,0))} -> 46395 | F24: {=INDEX(Schedule!$G$5:$G$47,MATCH($B24,Schedule!$B$5:$B$47,0))} -> 46406 | G24: {=INDEX(Schedule!$N$5:$N$47,MATCH($B24,Schedule!$B$5:$B$47,0))} -> 0
B25: A18 | C25: {=INDEX(Schedule!$C$5:$C$47,MATCH($B25,Schedule!$B$5:$B$47,0))} -> Model evaluation and evaluation report | D25: {=INDEX(Schedule!$E$5:$E$47,MATCH($B25,Schedule!$B$5:$B$47,0))} -> 5 | E25: {=INDEX(Schedule!$F$5:$F$47,MATCH($B25,Schedule!$B$5:$B$47,0))} -> 46407 | F25: {=INDEX(Schedule!$G$5:$G$47,MATCH($B25,Schedule!$B$5:$B$47,0))} -> 46413 | G25: {=INDEX(Schedule!$N$5:$N$47,MATCH($B25,Schedule!$B$5:$B$47,0))} -> 0
... B36: M6 | C36: {=INDEX(Schedule!$C$5:$C$47,MATCH($B36,Schedule!$B$5:$B$47,0))} -> Milestone: Project Closed | D36: {=INDEX(Schedule!$E$5:$E$47,MATCH($B36,Schedule!$B$5:$B$47,0))} -> 0 | E36: {=INDEX(Schedule!$F$5:$F$47,MATCH($B36,Schedule!$B$5:$B$47,0))} -> 46447 | F36: {=INDEX(Schedule!$G$5:$G$47,MATCH($B36,Schedule!$B$5:$B$47,0))} -> 46447 | G36: {=INDEX(Schedule!$N$5:$N$47,MATCH($B36,Schedule!$B$5:$B$47,0))} -> 0
B38: Table 2: Activities with float
B39: ID | C39: Activity | D39: Duration | E39: Start | F39: Finish | G39: Float (days)
B40: A02 | C40: {=INDEX(Schedule!$C$5:$C$47,MATCH($B40,Schedule!$B$5:$B$47,0))} -> Tools, access and environment setup (Power BI, Python, GitHub, API keys) | D40: {=INDEX(Schedule!$E$5:$E$47,MATCH($B40,Schedule!$B$5:$B$47,0))} -> 3 | E40: {=INDEX(Schedule!$F$5:$F$47,MATCH($B40,Schedule!$B$5:$B$47,0))} -> 46330 | F40: {=INDEX(Schedule!$G$5:$G$47,MATCH($B40,Schedule!$B$5:$B$47,0))} -> 46332 | G40: {=INDEX(Schedule!$N$5:$N$47,MATCH($B40,Schedule!$B$5:$B$47,0))} -> 1
B41: A07 | C41: {=INDEX(Schedule!$C$5:$C$47,MATCH($B41,Schedule!$B$5:$B$47,0))} -> Requirements workshops with ShopSmart managers | D41: {=INDEX(Schedule!$E$5:$E$47,MATCH($B41,Schedule!$B$5:$B$47,0))} -> 6 | E41: {=INDEX(Schedule!$F$5:$F$47,MATCH($B41,Schedule!$B$5:$B$47,0))} -> 46336 | F41: {=INDEX(Schedule!$G$5:$G$47,MATCH($B41,Schedule!$B$5:$B$47,0))} -> 46343 | G41: {=INDEX(Schedule!$N$5:$N$47,MATCH($B41,Schedule!$B$5:$B$47,0))} -> 11
B42: A09 | C42: {=INDEX(Schedule!$C$5:$C$47,MATCH($B42,Schedule!$B$5:$B$47,0))} -> Sales dashboard development | D42: {=INDEX(Schedule!$E$5:$E$47,MATCH($B42,Schedule!$B$5:$B$47,0))} -> 8 | E42: {=INDEX(Schedule!$F$5:$F$47,MATCH($B42,Schedule!$B$5:$B$47,0))} -> 46359 | F42: {=INDEX(Schedule!$G$5:$G$47,MATCH($B42,Schedule!$B$5:$B$47,0))} -> 46370 | G42: {=INDEX(Schedule!$N$5:$N$47,MATCH($B42,Schedule!$B$5:$B$47,0))} -> 18
B43: A10 | C43: {=INDEX(Schedule!$C$5:$C$47,MATCH($B43,Schedule!$B$5:$B$47,0))} -> Customer dashboard development | D43: {=INDEX(Schedule!$E$5:$E$47,MATCH($B43,Schedule!$B$5:$B$47,0))} -> 7 | E43: {=INDEX(Schedule!$F$5:$F$47,MATCH($B43,Schedule!$B$5:$B$47,0))} -> 46359 | F43: {=INDEX(Schedule!$G$5:$G$47,MATCH($B43,Schedule!$B$5:$B$47,0))} -> 46367 | G43: {=INDEX(Schedule!$N$5:$N$47,MATCH($B43,Schedule!$B$5:$B$47,0))} -> 19
B44: A11 | C44: {=INDEX(Schedule!$C$5:$C$47,MATCH($B44,Schedule!$B$5:$B$47,0))} -> Store performance dashboard development | D44: {=INDEX(Schedule!$E$5:$E$47,MATCH($B44,Schedule!$B$5:$B$47,0))} -> 6 | E44: {=INDEX(Schedule!$F$5:$F$47,MATCH($B44,Schedule!$B$5:$B$47,0))} -> 46371 | F44: {=INDEX(Schedule!$G$5:$G$47,MATCH($B44,Schedule!$B$5:$B$47,0))} -> 46378 | G44: {=INDEX(Schedule!$N$5:$N$47,MATCH($B44,Schedule!$B$5:$B$47,0))} -> 18
B45: A12 | C45: {=INDEX(Schedule!$C$5:$C$47,MATCH($B45,Schedule!$B$5:$B$47,0))} -> Inventory dashboard development | D45: {=INDEX(Schedule!$E$5:$E$47,MATCH($B45,Schedule!$B$5:$B$47,0))} -> 6 | E45: {=INDEX(Schedule!$F$5:$F$47,MATCH($B45,Schedule!$B$5:$B$47,0))} -> 46370 | F45: {=INDEX(Schedule!$G$5:$G$47,MATCH($B45,Schedule!$B$5:$B$47,0))} -> 46377 | G45: {=INDEX(Schedule!$N$5:$N$47,MATCH($B45,Schedule!$B$5:$B$47,0))} -> 19
B46: A13 | C46: {=INDEX(Schedule!$C$5:$C$47,MATCH($B46,Schedule!$B$5:$B$47,0))} -> Executive analytics report | D46: {=INDEX(Schedule!$E$5:$E$47,MATCH($B46,Schedule!$B$5:$B$47,0))} -> 4 | E46: {=INDEX(Schedule!$F$5:$F$47,MATCH($B46,Schedule!$B$5:$B$47,0))} -> 46379 | F46: {=INDEX(Schedule!$G$5:$G$47,MATCH($B46,Schedule!$B$5:$B$47,0))} -> 46386 | G46: {=INDEX(Schedule!$N$5:$N$47,MATCH($B46,Schedule!$B$5:$B$47,0))} -> 18
B47: A15 | C47: {=INDEX(Schedule!$C$5:$C$47,MATCH($B47,Schedule!$B$5:$B$47,0))} -> Sales forecasting model development | D47: {=INDEX(Schedule!$E$5:$E$47,MATCH($B47,Schedule!$B$5:$B$47,0))} -> 12 | E47: {=INDEX(Schedule!$F$5:$F$47,MATCH($B47,Schedule!$B$5:$B$47,0))} -> 46380 | F47: {=INDEX(Schedule!$G$5:$G$47,MATCH($B47,Schedule!$B$5:$B$47,0))} -> 46400 | G47: {=INDEX(Schedule!$N$5:$N$47,MATCH($B47,Schedule!$B$5:$B$47,0))} -> 4
B48: A19 | C48: {=INDEX(Schedule!$C$5:$C$47,MATCH($B48,Schedule!$B$5:$B$47,0))} -> Prompt library design and testing | D48: {=INDEX(Schedule!$E$5:$E$47,MATCH($B48,Schedule!$B$5:$B$47,0))} -> 8 | E48: {=INDEX(Schedule!$F$5:$F$47,MATCH($B48,Schedule!$B$5:$B$47,0))} -> 46359 | F48: {=INDEX(Schedule!$G$5:$G$47,MATCH($B48,Schedule!$B$5:$B$47,0))} -> 46370 | G48: {=INDEX(Schedule!$N$5:$N$47,MATCH($B48,Schedule!$B$5:$B$47,0))} -> 4
B49: A20 | C49: {=INDEX(Schedule!$C$5:$C$47,MATCH($B49,Schedule!$B$5:$B$47,0))} -> Retail report generator | D49: {=INDEX(Schedule!$E$5:$E$47,MATCH($B49,Schedule!$B$5:$B$47,0))} -> 7 | E49: {=INDEX(Schedule!$F$5:$F$47,MATCH($B49,Schedule!$B$5:$B$47,0))} -> 46371 | F49: {=INDEX(Schedule!$G$5:$G$47,MATCH($B49,Schedule!$B$5:$B$47,0))} -> 46379 | G49: {=INDEX(Schedule!$N$5:$N$47,MATCH($B49,Schedule!$B$5:$B$47,0))} -> 4
B50: A21 | C50: {=INDEX(Schedule!$C$5:$C$47,MATCH($B50,Schedule!$B$5:$B$47,0))} -> AI Retail Copilot development (Streamlit) | D50: {=INDEX(Schedule!$E$5:$E$47,MATCH($B50,Schedule!$B$5:$B$47,0))} -> 12 | E50: {=INDEX(Schedule!$F$5:$F$47,MATCH($B50,Schedule!$B$5:$B$47,0))} -> 46380 | F50: {=INDEX(Schedule!$G$5:$G$47,MATCH($B50,Schedule!$B$5:$B$47,0))} -> 46400 | G50: {=INDEX(Schedule!$N$5:$N$47,MATCH($B50,Schedule!$B$5:$B$47,0))} -> 4
B51: A22 | C51: {=INDEX(Schedule!$C$5:$C$47,MATCH($B51,Schedule!$B$5:$B$47,0))} -> Copilot integration with data and forecasting model | D51: {=INDEX(Schedule!$E$5:$E$47,MATCH($B51,Schedule!$B$5:$B$47,0))} -> 5 | E51: {=INDEX(Schedule!$F$5:$F$47,MATCH($B51,Schedule!$B$5:$B$47,0))} -> 46401 | F51: {=INDEX(Schedule!$G$5:$G$47,MATCH($B51,Schedule!$B$5:$B$47,0))} -> 46407 | G51: {=INDEX(Schedule!$N$5:$N$47,MATCH($B51,Schedule!$B$5:$B$47,0))} -> 4
